[0m09:20:53.081835 [debug] [MainThread]: Sending event: {'category': 'dbt', 'action': 'invocation', 'label': 'start', 'context': [<snowplow_tracker.self_describing_json.SelfDescribingJson object at 0x7e4df4db2420>, <snowplow_tracker.self_describing_json.SelfDescribingJson object at 0x7e4df6768080>, <snowplow_tracker.self_describing_json.SelfDescribingJson object at 0x7e4df4db3b30>]}


============================== 09:20:53.091031 | a005b064-7ec6-40f2-bf9c-389c5af83d64 ==============================
[0m09:20:53.091031 [info ] [MainThread]: Running with dbt=1.9.0
[0m09:20:53.091693 [debug] [MainThread]: running dbt with arguments {'printer_width': '80', 'indirect_selection': 'eager', 'log_cache_events': 'False', 'write_json': 'True', 'partial_parse': 'True', 'cache_selected_only': 'False', 'profiles_dir': '/root/.dbt', 'debug': 'False', 'fail_fast': 'False', 'log_path': 'logs', 'warn_error': 'None', 'version_check': 'True', 'use_colors': 'True', 'use_experimental_parser': 'False', 'no_print': 'None', 'quiet': 'False', 'empty': 'False', 'log_format': 'default', 'static_parser': 'True', 'introspect': 'True', 'invocation_command': 'dbt run', 'target_path': 'None', 'warn_error_options': 'WarnErrorOptions(include=[], exclude=[])', 'send_anonymous_usage_stats': 'True'}
[0m09:20:53.092199 [error] [MainThread]: Encountered an error:
Runtime Error
  No dbt_project.yml found at expected path /usr/app/dbt_project.yml
  Verify that each entry within packages.yml (and their transitive dependencies) contains a file named dbt_project.yml
  
[0m09:20:53.093751 [debug] [MainThread]: Resource report: {"command_name": "run", "command_success": false, "command_wall_clock_time": 0.06938126, "process_in_blocks": "0", "process_kernel_time": 0.254121, "process_mem_max_rss": "86524", "process_out_blocks": "1472", "process_user_time": 1.380725}
[0m09:20:53.094638 [debug] [MainThread]: Command `dbt run` failed at 09:20:53.094371 after 0.07 seconds
[0m09:20:53.095163 [debug] [MainThread]: Sending event: {'category': 'dbt', 'action': 'invocation', 'label': 'end', 'context': [<snowplow_tracker.self_describing_json.SelfDescribingJson object at 0x7e4df4aa75f0>, <snowplow_tracker.self_describing_json.SelfDescribingJson object at 0x7e4df4aa5a30>, <snowplow_tracker.self_describing_json.SelfDescribingJson object at 0x7e4df4aa1a90>]}
[0m09:20:53.095622 [debug] [MainThread]: Flushing usage events
[0m09:20:53.939120 [debug] [MainThread]: An error was encountered while trying to flush usage events
[0m09:21:37.657411 [debug] [MainThread]: Sending event: {'category': 'dbt', 'action': 'invocation', 'label': 'start', 'context': [<snowplow_tracker.self_describing_json.SelfDescribingJson object at 0x794114ec6030>, <snowplow_tracker.self_describing_json.SelfDescribingJson object at 0x7941168b0290>, <snowplow_tracker.self_describing_json.SelfDescribingJson object at 0x794114d09580>]}


============================== 09:21:37.665306 | 4bc22d3a-ab38-4079-b79c-19e4d5b35455 ==============================
[0m09:21:37.665306 [info ] [MainThread]: Running with dbt=1.9.0
[0m09:21:37.665904 [debug] [MainThread]: running dbt with arguments {'printer_width': '80', 'indirect_selection': 'eager', 'write_json': 'True', 'log_cache_events': 'False', 'partial_parse': 'True', 'cache_selected_only': 'False', 'warn_error': 'None', 'fail_fast': 'False', 'debug': 'False', 'log_path': 'logs', 'version_check': 'True', 'profiles_dir': '/root/.dbt', 'use_colors': 'True', 'use_experimental_parser': 'False', 'empty': 'False', 'quiet': 'False', 'no_print': 'None', 'warn_error_options': 'WarnErrorOptions(include=[], exclude=[])', 'introspect': 'True', 'log_format': 'default', 'invocation_command': 'dbt run', 'target_path': 'None', 'static_parser': 'True', 'send_anonymous_usage_stats': 'True'}
[0m09:21:37.666334 [error] [MainThread]: Encountered an error:
Runtime Error
  No dbt_project.yml found at expected path /usr/app/dbt_project.yml
  Verify that each entry within packages.yml (and their transitive dependencies) contains a file named dbt_project.yml
  
[0m09:21:37.667615 [debug] [MainThread]: Resource report: {"command_name": "run", "command_success": false, "command_wall_clock_time": 0.05651826, "process_in_blocks": "0", "process_kernel_time": 0.231, "process_mem_max_rss": "86732", "process_out_blocks": "1472", "process_user_time": 1.188601}
[0m09:21:37.668255 [debug] [MainThread]: Command `dbt run` failed at 09:21:37.668060 after 0.06 seconds
[0m09:21:37.668515 [debug] [MainThread]: Sending event: {'category': 'dbt', 'action': 'invocation', 'label': 'end', 'context': [<snowplow_tracker.self_describing_json.SelfDescribingJson object at 0x7941168b0290>, <snowplow_tracker.self_describing_json.SelfDescribingJson object at 0x794114ef3fb0>, <snowplow_tracker.self_describing_json.SelfDescribingJson object at 0x7941148f7e90>]}
[0m09:21:37.668760 [debug] [MainThread]: Flushing usage events
[0m09:21:38.496432 [debug] [MainThread]: An error was encountered while trying to flush usage events
[0m09:22:36.619836 [debug] [MainThread]: Sending event: {'category': 'dbt', 'action': 'invocation', 'label': 'start', 'context': [<snowplow_tracker.self_describing_json.SelfDescribingJson object at 0x786f2a4e4b30>, <snowplow_tracker.self_describing_json.SelfDescribingJson object at 0x786f2be9c260>, <snowplow_tracker.self_describing_json.SelfDescribingJson object at 0x786f2a4e4ad0>]}


============================== 09:22:36.625864 | 65b65be3-dc00-475f-9ab7-03ed0fd5db80 ==============================
[0m09:22:36.625864 [info ] [MainThread]: Running with dbt=1.9.0
[0m09:22:36.626408 [debug] [MainThread]: running dbt with arguments {'printer_width': '80', 'indirect_selection': 'eager', 'log_cache_events': 'False', 'write_json': 'True', 'partial_parse': 'True', 'cache_selected_only': 'False', 'warn_error': 'None', 'debug': 'False', 'fail_fast': 'False', 'log_path': 'logs', 'version_check': 'True', 'profiles_dir': '/root/.dbt', 'use_colors': 'True', 'use_experimental_parser': 'False', 'empty': 'False', 'quiet': 'False', 'no_print': 'None', 'log_format': 'default', 'static_parser': 'True', 'invocation_command': 'dbt run', 'introspect': 'True', 'target_path': 'None', 'warn_error_options': 'WarnErrorOptions(include=[], exclude=[])', 'send_anonymous_usage_stats': 'True'}
[0m09:22:36.626820 [error] [MainThread]: Encountered an error:
Runtime Error
  No dbt_project.yml found at expected path /usr/app/dbt_project.yml
  Verify that each entry within packages.yml (and their transitive dependencies) contains a file named dbt_project.yml
  
[0m09:22:36.627791 [debug] [MainThread]: Resource report: {"command_name": "run", "command_success": false, "command_wall_clock_time": 0.046848606, "process_in_blocks": "0", "process_kernel_time": 0.177159, "process_mem_max_rss": "86540", "process_out_blocks": "1472", "process_user_time": 0.995468}
[0m09:22:36.628344 [debug] [MainThread]: Command `dbt run` failed at 09:22:36.628228 after 0.05 seconds
[0m09:22:36.628698 [debug] [MainThread]: Sending event: {'category': 'dbt', 'action': 'invocation', 'label': 'end', 'context': [<snowplow_tracker.self_describing_json.SelfDescribingJson object at 0x786f2a9eb140>, <snowplow_tracker.self_describing_json.SelfDescribingJson object at 0x786f29f17a40>, <snowplow_tracker.self_describing_json.SelfDescribingJson object at 0x786f29f59010>]}
[0m09:22:36.629090 [debug] [MainThread]: Flushing usage events
[0m09:22:37.449442 [debug] [MainThread]: An error was encountered while trying to flush usage events
